Workbook

Sheet PRESUPUESTO
A1: #VALUE! | C1: CODIGO | D1: PROYECTO | E1: FECHA DE MODIFICACIÓN: | F1: M2 | H1: Ancho | I1: Fondo | J1: Complejidad | M1: € Empresa | N1: Markup | O1: €+Margen | P1: Ben.Bruto | Q1: €/M2
E2: =NOW() | F2: =H2*I2 | M2: =M14+M46+M54+M59+M64+M69+M74+M78+M87+M111+M119+M122+M126+M132+M144+M169 | N2: 1 | O2: =O14+O46+O54+O59+O64+O69+O74+O78+O87+O111+O119+O122+O126+O132+O144+O169 | P2: =P14+P46+P54+P59+P64+P69+P74+P78+P87+P111+P119+P122+P126+P132+P144+P169 | Q2: =IFERROR(O2/F2,0)
A4: FAMILIA | B4: SUB F. | C4: MATERIAL | D4: TARIMA | E4: COMENTARIOS | F4: Largo | G4: Ancho | I4: m2 | J4: UDS | K4: €/m2 | L4: €/m2 Real | M4: €/Empresa | N4: Markup % | O4: € TOTAL | P4: BEN.EMP | Q4: COSTE TOT | R4: Diseño (50m2/4-6h) | S4: COSTE MAT | T4: Tarima Mala | U4: (35m2/h) Corte | V4: Merma 20% | W4: Tarima Buena | X4: Corte | Y4: Merma 20 % | Z4: Rastreles ® | AA4: (15m2/h) T. Corte | AB4: (1,6m2/h) T.Montaje | AC4: Zocalo | AD4: Corte | AE4: Perfil Alu. | AF4: Plastico | AG4: Tornilleria | AH4: (30m2/h) T. Paletizacion | AI4: Palets
A5: Tarima | B5: Suelo | C5: Aglomerado Reciclado | D5: Tarima con Moqueta | F5: 0 | G5: 0 | I5: =F5*G5 | J5: 0 | K5: 7.77 | L5: =IFERROR(ROUNDUP((Q5/I5)/0.5,0)*0.5,0) | M5: =IF(I5=0,J5*K5,I5*J5*K5) | N5: =$N$14 | O5: =SUM(M5*N5)+M5 | P5: =SUM(O5-M5) | Q5: =R5+S5 | R5: =J5*(MAX(1,ROUNDUP(I5/50,0)*4)*COSTE!$G$3) | S5: =SUM(T5:AU5) | T5: =(I5*COSTE!$G$20)/3 | U5: =(I5/35)*COSTE!$G$4 | V5: =T5*20% | Z5: =(((((2*F5)+1)*G5)*0.08)*COSTE!$G$21)/3 | AA5: =(((((2*F5)+1)*G5)*0.08)/15)*COSTE!$G$4 | AC5: =((((F5*2)+(G5*2))*0.1)*2.44)*COSTE!$G$23 | AD5: =((((F5*2)+(G5*2))*0.1)*2.44)*COSTE!$J$23 | AE5: =((F5*2)+(G5*2))*COSTE!$G$55 | AF5: =I5*COSTE!$G$66 | AG5: =I5*0.1 | AH5: =(I5/30)*COSTE!$G$5 | AI5: =ROUNDUP(I5/35,0)*((COSTE!$G$20/3)+(COSTE!$G$45*1)+(COSTE!$G$4/6)+(0.5))
A6: Tarima | B6: Suelo | C6: Melamina Reciclado | D6: Tarima Melamina Reciclada | F6: 0 | G6: 0 | I6: =F6*G6 | J6: 0 | K6: 22 | L6: =IFERROR(ROUNDUP((Q6/I6)/0.5,0)*0.5,0) | M6: =IF(I6=0,J6*K6,I6*J6*K6) | N6: =$N$14 | O6: =SUM(M6*N6)+M6 | P6: =SUM(O6-M6) | Q6: =R6+S6 | R6: =J6*(MAX(1,ROUNDUP(I6/50,0)*6)*COSTE!$G$3) | S6: =SUM(T6:AU6) | T6: =(I6*COSTE!$G$20)/3 | U6: =(I6/35)*COSTE!$G$4 | V6: =T6*20% | W6: =(I6*COSTE!$G$14) | X6: =I6*COSTE!$J$14 | Y6: =W6*20% | Z6: =((((((2*F6)+1)*G6)*0.08)*2)*COSTE!$G$21)/3 | AA6: =((((((2*F6)+1)*G6)*0.08)*2)/15)*COSTE!$G$4 | AB6: =(((((2*F7)+1)*G7)*0.08)/1.6)*COSTE!$G$4 | AC6: =((((F6*2)+(G6*2))*0.1)*2.44)*COSTE!$G$23 | AD6: =((((F6*2)+(G6*2))*0.1)*2.44)*COSTE!$J$23 | AE6: =((F6*2)+(G6*2))*COSTE!$G$55 | AF6: =I6*COSTE!$G$66 | AG6: =I6*0.1 | AH6: =((I6*2)/30)*COSTE!$G$5 | AI6: =ROUNDUP((I6*2)/35,0)*((COSTE!$G$20/3)+(COSTE!$G$45*1)+(COSTE!$G$4/6)+(0.5))
A7: Tarima | B7: Suelo | C7: Melamina | D7: Tarima Melamina Nueva | E7: *New | F7: 0 | G7: 0 | I7: =F7*G7 | J7: 0 | K7: 30 | L7: =IFERROR(ROUNDUP((Q7/I7)/0.5,0)*0.5,0) | M7: =IF(I7=0,J7*K7,I7*J7*K7) | N7: =$N$14 | O7: =SUM(M7*N7)+M7 | P7: =SUM(O7-M7) | Q7: =R7+S7 | R7: =J7*MAX(1,ROUNDUP(I7/50,0)*6)*COSTE!$G$3 | S7: =SUM(T7:AU7) | T7: =I7*COSTE!$G$20 | U7: =I7*COSTE!$J$20 | V7: =T7*20% | W7: =I7*COSTE!$G$14 | X7: =I7*COSTE!$J$14 | Y7: =W7*20% | Z7: =((((((2*F7)+1)*G7)*0.08)*2)*COSTE!$G$21)/3 | AA7: =((((((2*F7)+1)*G7)*0.08)*2)/15)*COSTE!$G$4 | AB7: =(((((2*F5)+1)*G5)*0.08)/1.6)*COSTE!$G$4 | AC7: =((((F7*2)+(G7*2))*0.1)*2.44)*COSTE!$G$23 | AD7: =((((F7*2)+(G7*2))*0.1)*2.44)*COSTE!$J$23 | AE7: =((F7*2)+(G7*2))*COSTE!$G$55 | AF7: =I7*COSTE!$G$66 | AG7: =I7*0.1
A8: Tarima | B8: Suelo | C8: Melamina Especial | D8: Tarima Melamina Especial | F8: 0 | G8: 0 | I8: =F8*G8 | J8: 0 | K8: 32.58 | L8: =IFERROR(ROUNDUP((Q8/I8)/0.5,0)*0.5,0) | M8: =IF(I8=0,J8*K8,I8*J8*K8) | N8: =$N$14 | O8: =SUM(M8*N8)+M8 | P8: =SUM(O8-M8) | Q8: =R8+S8 | R8: =J8*MAX(1,ROUNDUP(I8/50,0)*6)*COSTE!$G$3 | S8: =SUM(T8:AU8) | T8: =(I8*COSTE!$G$20)/3 | U8: =(I8/35)*COSTE!$G$4 | V8: =T8*20% | W8: =(I8*COSTE!$G$17) | X8: =I8*COSTE!$J$17 | Y8: =W8*20% | Z8: =((((((2*F8)+1)*G8)*0.08)*2)*COSTE!$G$21)/3 | AA8: =((((((2*F8)+1)*G8)*0.08)*2)/15)*COSTE!$G$4 | AB8: =(((((2*F6)+1)*G6)*0.08)/1.6)*COSTE!$G$4 | AC8: =((((F8*2)+(G8*2))*0.1)*2.44)*COSTE!$G$23 | AD8: =((((F8*2)+(G8*2))*0.1)*2.44)*COSTE!$J$23 | AE8: =((F8*2)+(G8*2))*COSTE!$G$55 | AF8: =I8*COSTE!$G$66 | AG8: =I8*0.1 | AH8: =((I8*2)/30)*COSTE!$G$5 | AI8: =ROUNDUP((I8*2)/35,0)*((COSTE!$G$20/3)+(COSTE!$G$45*1)+(COSTE!$G$4/6)+(0.5))
A9: FAMILIA | B9: SUB F. | C9: MATERIAL | D9: TARIMA - RAMPA | E9: COMENTARIOS | F9: Fondo | G9: Ancho | I9: m2 | J9: UDS | K9: €/m2 | L9: €/m2 Real | M9: €/Empresa | N9: Markup % | O9: € TOTAL | P9: BEN.EMP | Q9: COSTE TOT | R9: Diseño (1uni/1h) | S9: COSTE MAT | T9: Perfil Alu. | U9: (1m2/h) T. Fabricación
A10: Tarima | B10: Rampa | C10: Tarima | D10: Rampa (Estandar 1x1) | E10: *El coste rampa lo pondria siempre igual por m2 ya que el valor del material esta en la tarima | F10: 0 | G10: 0 | I10: =F10*G10 | J10: 0 | K10: 28 | L10: =IFERROR(ROUNDUP((Q10/I10)/0.5,0)*0.5,0) | M10: =IF(I10=0,J10*K10,I10*J10*K10) | N10: =$N$14 | O10: =SUM(M10*N10)+M10 | P10: =SUM(O10-M10) | Q10: =R10+S10 | R10: =J10*MAX(1,ROUNDUP(J10/1,0)*1)*COSTE!$G$3 | S10: =SUM(T10:AU10) | T10: =(F10*2)*COSTE!$G$55 | U10: =I10*COSTE!$G$5
A11: FAMILIA | B11: SUB F. | C11: MATERIAL | D11: TARIMA - REGATA LED | E11: COMENTARIOS | I11: ml | J11: UDS | K11: €/ml | L11: €/ml Real | M11: €/Empresa | N11: Markup % | O11: € TOTAL | P11: BEN.EMP | Q11: COSTE TOT | R11: Diseño (10ml/2h) | S11: COSTE MAT | T11: (4 ml/h) T. Fabricación | U11: (2 ml/h) T. Fabricación
A12: Tarima | B12: Proceso | C12: Regata | D12: Regata Led Recta | I12: 0 | J12: 0 | K12: 5 | L12: =IFERROR(ROUNDUP((Q12/I12)/0.5,0)*0.5,0) | M12: =IF(I12=0,J12*K12,I12*J12*K12) | N12: =$N$14 | O12: =SUM(M12*N12)+M12 | P12: =SUM(O12-M12) | Q12: =R12+S12 | R12: =J12*(MAX(1,ROUNDUP(I12/10,0)*2)*COSTE!$G$3) | S12: =SUM(T12:AU12) | T12: =(I12/4)*COSTE!$G$5
A13: Tarima | B13: Proceso | C13: Regata | D13: Regata Led Diagonal o Curva | I13: 0 | J13: 0 | K13: 10 | L13: =IFERROR(ROUNDUP((Q13/I13)/0.5,0)*0.5,0) | M13: =IF(I13=0,J13*K13,I13*J13*K13) | N13: =$N$14 | O13: =SUM(M13*N13)+M13 | P13: =SUM(O13-M13) | Q13: =R13+S13 | R13: =J13*(MAX(1,ROUNDUP(I13/10,0)*2)*COSTE!$G$3) | S13: =SUM(T13:AU13) | U13: =(I13/2)*COSTE!$G$5
K14: TOTAL TARIMA | M14: =SUM(M5:M13) | N14: =$N$2 | O14: =SUM(O5:O13) | P14: =SUM(P5:P13) | Q14: =SUM(Q5:Q13) | S14: =SUM(S5:S13)
A15: FAMILIA | B15: SUB F. | C15: MATERIAL | D15: MURO | E15: COMENTARIOS | F15: Largo | G15: Altura | H15: Grosor | I15: m2 | J15: UDS | K15: €/m2 | L15: €/m2+G Real | M15: €/Empresa | N15: Markup % | O15: € TOTAL | P15: BEN.EMP | Q15: COSTE TOT | R15: Diseño 20m2/5h) | S15: COSTE MAT | T15: Tableros | U15: Corte | V15: Cadel | W15: Merma 20% | X15: Rastreles (r) | Y15: (15m2/h) Corte | Z15: Columnas | AA15: (15m2/h) Corte | AB15: (7,5 m2/h) Montaje | AC15: Almas | AD15: Corte | AE15: Yapasas | AF15: (30m2/h) T. Paletizacion | AG15: Palets | AH15: Tornilleria
A16: Muro | B16: Paredes | C16: Aglomerado | D16: 1 Cara (Grosor Estandar 0,1m / Altura 2,75m) | E16: *El grosor se pone en el excel | F16: 0 | G16: 0 | H16: 0 | I16: =F16*G16 | J16: 0 | K16: 14 | L16: =IFERROR(ROUNDUP((Q16/I16)/0.5,0)*0.5,0) | M16: =IF(I16=0,J16*K16,I16*J16*K16) | N16: =$N$46 | O16: =SUM(M16*N16)+M16 | P16: =SUM(O16-M16) | Q16: =R16+S16 | R16: =J16*(MAX(1,ROUNDUP(I16/20,0)*5)*COSTE!$G$3) | S16: =SUM(T16:AU16) | T16: =((F16*G16) + ((H16*G16)*2))*COSTE!$G$20 | U16: =((F16*G16) + ((H16*G16)*2))*COSTE!$J$20 | W16: =T16*20% | X16: =(((F16*(H16-(0.016*2)))*2)*COSTE!$G$20)/3 | Y16: =(((F16*(H16-(0.016*2)))*2)/15)*COSTE!$G$4 | Z16: =((F16+1)*(((0.08*G16)*2)+((H16-(0.016*4))*G16)))*COSTE!$G$20 | AA16: =(((F16+1)*(((0.08*G16)*2)+((H16-(0.016*4))*G16)))/15)*COSTE!$G$4 | AB16: =(((F16+1)*(((0.08*G16)*2)+((H16-(0.016*4))*G16)))/7.5)*COSTE!$G$4 | AF16: =(I16/30)*COSTE!$G$5 | AG16: =ROUNDUP(I16/35,0)*((COSTE!$G$20/3)+(COSTE!$G$45*1)+(COSTE!$G$4/6)+(0.5)) | AH16: =I16*0.1
A17: Muro | B17: Paredes | C17: Aglomerado | D17: 2 Cara (Grosor Estandar 0,1m / Altura 2,75m) | E17: *El grosor se pone en el excel | F17: 0 | G17: 0 | H17: 0 | I17: =F17*G17 | J17: 0 | K17: 22 | L17: =IFERROR(ROUNDUP((Q17/I17)/0.5,0)*0.5,0) | M17: =IF(I17=0,J17*K17,I17*J17*K17) | N17: =$N$46 | O17: =SUM(M17*N17)+M17 | P17: =SUM(O17-M17) | Q17: =R17+S17 | R17: =J17*(MAX(1,ROUNDUP(I17/20,0)*5)*COSTE!$G$3) | S17: =SUM(T17:AU17) | T17: =(((F17*G17) + ((H17*G17)*2))*2)*COSTE!$G$20 | U17: =(((F17*G17) + ((H17*G17)*2))*2)*COSTE!$J$20 | W17: =T17*20% | X17: =(((F17*(H17-(0.016*2)))*2)*COSTE!$G$20)/3 | Y17: =(((F17*(H17-(0.016*2)))*2)/15)*COSTE!$G$4 | Z17: =((F17+1)*(((0.08*G17)*2)+((H17-(0.016*4))*G17)))*COSTE!$G$20 | AA17: =(((F17+1)*(((0.08*G17)*2)+((H17-(0.016*4))*G17)))/15)*COSTE!$G$4 | AB17: =(((F17+1)*(((0.08*G17)*2)+((H17-(0.016*4))*G17)))/7.5)*COSTE!$G$4 | AF17: =(I17/30)*COSTE!$G$5 | AG17: =ROUNDUP(I17/35,0)*((COSTE!$G$20/3)+(COSTE!$G$45*1)+(COSTE!$G$4/6)+(0.5)) | AH17: =I17*0.1
A18: Muro | B18: Paredes | C18: MDF | D18: 1 Cara (Grosor Estandar 0,1m / Altura 2,75m) | E18: *El grosor se pone en el excel | F18: 0 | G18: 0 | H18: 0 | I18: =F18*G18 | J18: 0 | K18: 21 | L18: =IFERROR(ROUNDUP((Q18/I18)/0.5,0)*0.5,0) | M18: =IF(I18=0,J18*K18,I18*J18*K18) | N18: =$N$46 | O18: =SUM(M18*N18)+M18 | P18: =SUM(O18-M18) | Q18: =R18+S18 | R18: =J18*(MAX(1,ROUNDUP(I18/20,0)*5)*COSTE!$G$3) | S18: =SUM(T18:AU18) | T18: =((F18*G18) + ((H18*G18)*2))*COSTE!$G$27 | U18: =((F18*G18) + ((H18*G18)*2))*COSTE!$J$27 | W18: =T18*20% | X18: =(((F18*(H18-(0.016*2)))*2)*COSTE!$G$20)/3 | Y18: =(((F18*(H18-(0.016*2)))*2)/15)*COSTE!$G$4 | Z18: =((F18+1)*(((0.08*G18)*2)+((H18-(0.016*4))*G18)))*COSTE!$G$20 | AA18: =(((F18+1)*(((0.08*G18)*2)+((H18-(0.016*4))*G18)))/15)*COSTE!$G$4 | AB18: =(((F18+1)*(((0.08*G18)*2)+((H18-(0.016*4))*G18)))/7.5)*COSTE!$G$4 | AF18: =(I18/30)*COSTE!$G$5 | AG18: =ROUNDUP(I18/35,0)*((COSTE!$G$20/3)+(COSTE!$G$45*1)+(COSTE!$G$4/6)+(0.5)) | AH18: =I18*0.1
A19: Muro | B19: Paredes | C19: MDF | D19: 2 Cara (Grosor Estandar 0,1m/ Altura 2,75m) | E19: *El grosor se pone en el excel | F19: 0 | G19: 0 | H19: 0 | I19: =F19*G19 | J19: 0 | K19: 34 | L19: =IFERROR(ROUNDUP((Q19/I19)/0.5,0)*0.5,0) | M19: =IF(I19=0,J19*K19,I19*J19*K19) | N19: =$N$46 | O19: =SUM(M19*N19)+M19 | P19: =SUM(O19-M19) | Q19: =R19+S19 | R19: =J19*(MAX(1,ROUNDUP(I19/20,0)*5)*COSTE!$G$3) | S19: =SUM(T19:AU19) | T19: =(((F19*G19) + ((H19*G19)*2))*2)*COSTE!$G$27 | U19: =(((F19*G19) + ((H19*G19)*2))*2)*COSTE!$J$27 | W19: =T19*20% | X19: =(((F19*(H19-(0.016*2)))*2)*COSTE!$G$20)/3 | Y19: =(((F19*(H19-(0.016*2)))*2)/15)*COSTE!$G$4 | Z19: =((F19+1)*(((0.08*G19)*2)+((H19-(0.016*4))*G19)))*COSTE!$G$20 | AA19: =(((F19+1)*(((0.08*G19)*2)+((H19-(0.016*4))*G19)))/15)*COSTE!$G$4 | AB19: =(((F19+1)*(((0.08*G19)*2)+((H19-(0.016*4))*G19)))/7.5)*COSTE!$G$4 | AF19: =(I19/30)*COSTE!$G$5 | AG19: =ROUNDUP(I19/35,0)*((COSTE!$G$20/3)+(COSTE!$G$45*1)+(COSTE!$G$4/6)+(0.5)) | AH19: =I19*0.1
A20: Muro | B20: Paredes | C20: Melamina | D20: 1 Cara (Grosor Estandar 0,1m / Altura 2,75m) | E20: *El grosor se pone en el excel | F20: 0 | G20: 0 | H20: 0 | I20: =F20*G20 | J20: 0 | K20: 15 | L20: =IFERROR(ROUNDUP((Q20/I20)/0.5,0)*0.5,0) | M20: =IF(I20=0,J20*K20,I20*J20*K20) | N20: =$N$46 | O20: =SUM(M20*N20)+M20 | P20: =SUM(O20-M20) | Q20: =R20+S20 | R20: =J20*(MAX(1,ROUNDUP(I20/20,0)*5)*COSTE!$G$3) | S20: =SUM(T20:AU20) | T20: =((F20*G20) + ((H20*G20)*2))*COSTE!$G$13 | U20: =((F20*G20) + ((H20*G20)*2))*COSTE!$J$13 | V20: =((F20*G20) + ((H20*G20)*2))*COSTE!$L$13 | W20: =T20*20% | X20: =(((F20*(H20-(0.016*2)))*2)*COSTE!$G$20)/3 | Y20: =(((F20*(H20-(0.016*2)))*2)/15)*COSTE!$G$4 | Z20: =((F20+1)*(((0.08*G20)*2)+((H20-(0.016*4))*G20)))*COSTE!$G$20 | AA20: =(((F20+1)*(((0.08*G20)*2)+((H20-(0.016*4))*G20)))/15)*COSTE!$G$4 | AB20: =(((F20+1)*(((0.08*G20)*2)+((H20-(0.016*4))*G20)))/7.5)*COSTE!$G$4 | AC20: =(((F20*G20)+F20)*0.027)*COSTE!$G$25 | AD20: =(((F20*G20)+F20)*0.027)*COSTE!J25 | AE20: =(F20*COSTE!$G$20)/3 | AF20: =(I20/30)*COSTE!$G$5 | AG20: =ROUNDUP(I20/35,0)*((COSTE!$G$20/3)+(COSTE!$G$45*1)+(COSTE!$G$4/6)+(0.5)) | AH20: =I20*0.1
A21: Muro | B21: Paredes | C21: Melamina | D21: 2 Cara (Grosor Estandar 0,1m / Altura 2,75m) | E21: *El grosor se pone en el excel | F21: 0 | G21: 0 | H21: 0 | I21: =F21*G21 | J21: 0 | K21: 25 | L21: =IFERROR(ROUNDUP((Q21/I21)/0.5,0)*0.5,0) | M21: =IF(I21=0,J21*K21,I21*J21*K21) | N21: =$N$46 | O21: =SUM(M21*N21)+M21 | P21: =SUM(O21-M21) | Q21: =R21+S21 | R21: =J21*(MAX(1,ROUNDUP(I21/20,0)*5)*COSTE!$G$3) | S21: =SUM(T21:AU21) | T21: =(((F21*G21) + ((H21*G21)*2))*2)*COSTE!$G$13 | U21: =(((F21*G21) + ((H21*G21)*2))*2)*COSTE!$J$13 | V21: =(((F21*G21) + ((H21*G21)*2))*2)*COSTE!$L$13 | W21: =T21*20% | X21: =(((F21*(H21-(0.016*2)))*2)*COSTE!$G$20)/3 | Y21: =(((F21*(H21-(0.016*2)))*2)/15)*COSTE!$G$4 | Z21: =((F21+1)*(((0.08*G21)*2)+((H21-(0.016*4))*G21)))*COSTE!$G$20 | AA21: =(((F21+1)*(((0.08*G21)*2)+((H21-(0.016*4))*G21)))/15)*COSTE!$G$4 | AB21: =(((F21+1)*(((0.08*G21)*2)+((H21-(0.016*4))*G21)))/7.5)*COSTE!$G$4 | AC21: =(((F21*G21)+F21)*0.027)*COSTE!$G$25 | AD21: =(((F21*G21)+F21)*0.027)*COSTE!J26 | AE21: =(F21*COSTE!$G$20)/3 | AF21: =(I21/30)*COSTE!$G$5 | AG21: =ROUNDUP(I21/35,0)*((COSTE!$G$20/3)+(COSTE!$G$45*1)+(COSTE!$G$4/6)+(0.5)) | AH21: =I21*0.1
A22: Muro | B22: Paredes | C22: Melamina Especial / Chopo | D22: 1 Cara (Grosor Estandar 0,1m/ Altura 2,75m) | E22: *El grosor se pone en el excel | F22: 0 | G22: 0 | H22: 0 | I22: =F22*G22 | J22: 0 | K22: 21 | L22: =IFERROR(ROUNDUP((Q22/I22)/0.5,0)*0.5,0) | M22: =IF(I22=0,J22*K22,I22*J22*K22) | N22: =$N$46 | O22: =SUM(M22*N22)+M22 | P22: =SUM(O22-M22) | Q22: =R22+S22 | R22: =J22*(MAX(1,ROUNDUP(I22/20,0)*5)*COSTE!$G$3) | S22: =SUM(T22:AU22) | T22: =((F22*G22) + ((H22*G22)*2))*COSTE!$G$17 | U22: =((F22*G22) + ((H22*G22)*2))*COSTE!$J$17 | V22: =((F22*G22) + ((H22*G22)*2))*COSTE!$L$17 | W22: =T22*20% | X22: =(((F22*(H22-(0.016*2)))*2)*COSTE!$G$20)/3 | Y22: =(((F22*(H22-(0.016*2)))*2)/15)*COSTE!$G$4 | Z22: =((F22+1)*(((0.08*G22)*2)+((H22-(0.016*4))*G22)))*COSTE!$G$20 | AA22: =(((F22+1)*(((0.08*G22)*2)+((H22-(0.016*4))*G22)))/15)*COSTE!$G$4 | AB22: =(((F22+1)*(((0.08*G22)*2)+((H22-(0.016*4))*G22)))/7.5)*COSTE!$G$4 | AC22: =(((F22*G22)+F22)*0.027)*COSTE!$G$25 | AD22: =(((F22*G22)+F22)*0.027)*COSTE!J27 | AE22: =(F22*COSTE!$G$20)/3 | AF22: =(I22/30)*COSTE!$G$5 | AG22: =ROUNDUP(I22/35,0)*((COSTE!$G$20/3)+(COSTE!$G$45*1)+(COSTE!$G$4/6)+(0.5)) | AH22: =I22*0.1
A23: Muro | B23: Paredes | C23: Melamina Especial / Chopo | D23: 2 Cara (Grosor Estandar 0,1m/ Altura 2,75m) | E23: *El grosor se pone en el excel | F23: 0 | G23: 0 | H23: 0 | I23: =F23*G23 | J23: 0 | K23: 36 | L23: =IFERROR(ROUNDUP((Q23/I23)/0.5,0)*0.5,0) | M23: =IF(I23=0,J23*K23,I23*J23*K23) | N23: =$N$46 | O23: =SUM(M23*N23)+M23 | P23: =SUM(O23-M23) | Q23: =R23+S23 | R23: =J23*(MAX(1,ROUNDUP(I23/20,0)*5)*COSTE!$G$3) | S23: =SUM(T23:AU23) | T23: =(((F23*G23) + ((H23*G23)*2))*2)*COSTE!$G$17 | U23: =(((F23*G23) + ((H23*G23)*2))*2)*COSTE!$J$17 | V23: =(((F23*G23) + ((H23*G23)*2))*2)*COSTE!$L$17 | W23: =T23*20% | X23: =(((F23*(H23-(0.016*2)))*2)*COSTE!$G$20)/3 | Y23: =(((F23*(H23-(0.016*2)))*2)/15)*COSTE!$G$4 | Z23: =((F23+1)*(((0.08*G23)*2)+((H23-(0.016*4))*G23)))*COSTE!$G$20 | AA23: =(((F23+1)*(((0.08*G23)*2)+((H23-(0.016*4))*G23)))/15)*COSTE!$G$4 | AB23: =(((F23+1)*(((0.08*G23)*2)+((H23-(0.016*4))*G23)))/7.5)*COSTE!$G$4 | AC23: =(((F23*G23)+F23)*0.027)*COSTE!$G$25 | AD23: =(((F23*G23)+F23)*0.027)*COSTE!J28 | AE23: =(F23*COSTE!$G$20)/3 | AF23: =(I23/30)*COSTE!$G$5 | AG23: =ROUNDUP(I23/35,0)*((COSTE!$G$20/3)+(COSTE!$G$45*1)+(COSTE!$G$4/6)+(0.5)) | AH23: =I23*0.1
A24: FAMILIA | B24: SUB F. | C24: MATERIAL | D24: MURO - BMATRIX | E24: COMENTARIOS | F24: Largo | G24: Altura | H24: Grosor | I24: m2 | J24: UDS | K24: €/m2 | L24: €/m2 Real | M24: €/Empresa | N24: Markup % | O24: € TOTAL | P24: BEN.EMP | Q24: COSTE TOT | R24: Diseño 20m2/6h) | S24: COSTE MAT | T24: Alquiler | U24: Logistica
A25: Muro | B25: Paredes | C25: Bmatrix | D25: Alquiler Muro Bmatrix | E25: *Modificar coste?? | F25: 0 | G25: 0 | H25: 0 | I25: =F25*G25 | J25: 0 | K25: 50 | L25: =IFERROR(ROUNDUP((Q25/I25)/0.5,0)*0.5,0) | M25: =IF(I25=0,J25*K25,I25*J25*K25) | N25: =$N$46 | O25: =SUM(M25*N25)+M25 | P25: =SUM(O25-M25) | Q25: =R25+S25 | R25: =J25*(MAX(1,ROUNDUP(I25/20,0)*6)*COSTE!$G$3) | S25: =SUM(T25:AU25) | T25: =(F25*G25)*COSTE!G64 | U25: =IF(J25=0,0,3*COSTE!G5)
A26: FAMILIA | B26: SUB F. | C26: MATERIAL | D26: MURO - PUERTA | E26: COMENTARIOS | J26: UDS | K26: €/Uni | L26: €/Uni Real | M26: €/Empresa | N26: Markup % | O26: € TOTAL | P26: BEN.EMP | Q26: COSTE TOT | R26: Diseño (1h x 1uni) | S26: COSTE MAT | T26: Puerta (/3) | U26: (2h) Compra | V26: Alquiler Maneta (/5) | W26: Palet | X26: (4 uni/h) T. Paletizacion | Y26: Material | Z26: 6h/uni Fabricacion
A27: Muro | B27: Puerta | C27: Pintar | D27: Puerta + Maneta Codigo | J27: 0 | K27: 85 | L27: =IFERROR(ROUNDUP((Q27/J27)/0.5,0)*0.5,0) | M27: =IF(J27=0,J27*K27,J27*K27) | N27: =$N$46 | O27: =SUM(M27*N27)+M27 | P27: =SUM(O27-M27) | Q27: =R27+S27 | R27: =J27*(MAX(1,ROUNDUP(J27/1,0)*1)*COSTE!$G$3) | S27: =SUM(T27:AU27) | T27: =J27*(54/3) | U27: =J27*((COSTE!$G$4*2)/3) | V27: =J27*(131/5) | W27: =IF(J27=0,0,(((COSTE!$G$20/3)+(COSTE!$G$45*1)+(COSTE!$G$4/6)+(0.5)))/2) | X27: =(J27/4)*COSTE!$G$5
A28: Muro | B28: Puerta | C28: Pintar | D28: Puerta + Maneta Normal | J28: 0 | K28: 65 | L28: =IFERROR(ROUNDUP((Q28/J28)/0.5,0)*0.5,0) | M28: =IF(J28=0,J28*K28,J28*K28) | N28: =$N$46 | O28: =SUM(M28*N28)+M28 | P28: =SUM(O28-M28) | Q28: =R28+S28 | R28: =J28*(MAX(1,ROUNDUP(J28/1,0)*1)*COSTE!$G$3) | S28: =SUM(T28:AU28) | T28: =J28*(54/3) | U28: =J28*((COSTE!$G$4*2)/3) | V28: =J28*(10/5) | W28: =IF(J28=0,0,(((COSTE!$G$20/3)+(COSTE!$G$45*1)+(COSTE!$G$4/6)+(0.5)))/2) | X28: =(J28/4)*COSTE!$G$5
A29: Muro | B29: Puerta | C29: Blanco Lacado | D29: Puerta Melamina 1 cara + Maneta Codigo | J29: 0 | K29: 300 | L29: =IFERROR(ROUNDUP((Q29/J29)/0.5,0)*0.5,0) | M29: =IF(J29=0,J29*K29,J29*K29) | N29: =$N$46 | O29: =SUM(M29*N29)+M29 | P29: =SUM(O29-M29) | Q29: =R29+S29 | R29: =J29*(MAX(1,ROUNDUP(J29/1,0)*1)*COSTE!$G$3) | S29: =SUM(T29:AU29) | T29: =J29*(210/3) | U29: =J29*((COSTE!$G$4*2)/3) | V29: =(131/5)*J29 | W29: =IF(J29=0,0,(((COSTE!$G$20/3)+(COSTE!$G$45*1)+(COSTE!$G$4/6)+(0.5)))/2) | X29: =(J29/4)*COSTE!$G$5
A30: Muro | B30: Puerta | C30: Blanco Lacado | D30: Puerta Melamina 1 cara + Maneta Normal | J30: 0 | K30: 300 | L30: =IFERROR(ROUNDUP((Q30/J30)/0.5,0)*0.5,0) | M30: =IF(J30=0,J30*K30,J30*K30) | N30: =$N$46 | O30: =SUM(M30*N30)+M30 | P30: =SUM(O30-M30) | Q30: =R30+S30 | R30: =J30*(MAX(1,ROUNDUP(J30/1,0)*1)*COSTE!$G$3) | S30: =SUM(T30:AU30) | T30: =J30*(210/3) | U30: =J30*((COSTE!$G$4*2)/3) | V30: =J30*(10/5) | W30: =IF(J30=0,0,(((COSTE!$G$20/3)+(COSTE!$G$45*1)+(COSTE!$G$4/6)+(0.5)))/2) | X30: =(J30/4)*COSTE!$G$5
A31: Muro | B31: Puerta | C31: Chopo | D31: Puerta para Pintar a Medida + Maneta Codigo | E31: *New | J31: 0 | K31: 257 | L31: =IFERROR(ROUNDUP((Q31/J31)/0.5,0)*0.5,0) | M31: =IF(J31=0,J31*K31,J31*K31) | N31: =$N$46 | O31: =SUM(M31*N31)+M31 | P31: =SUM(O31-M31) | Q31: =R31+S31 | R31: =J31*(MAX(1,ROUNDUP(J31/1,0)*1)*COSTE!$G$3) | S31: =SUM(T31:AU31) | V31: =J31*(131/5) | W31: =IF(J31=0,0,(((COSTE!$G$20/3)+(COSTE!$G$45*1)+(COSTE!$G$4/6)+(0.5)))/2) | X31: =(J31/4)*COSTE!$G$5 | Y31: =J31*((COSTE!$G$41*10)+(COSTE!$G$43*5)+(COSTE!$G$30 *1)+(COSTE!$G$34)+ 20) | Z31: =(6*COSTE!$G$4)*J31
A32: Muro | B32: Puerta | C32: Chopo | D32: Puerta para Pintar a Medida + Maneta Normal | E32: *New | J32: 0 | K32: 233 | L32: =IFERROR(ROUNDUP((Q32/J32)/0.5,0)*0.5,0) | M32: =IF(J32=0,J32*K32,J32*K32) | N32: =$N$46 | O32: =SUM(M32*N32)+M32 | P32: =SUM(O32-M32) | Q32: =R32+S32 | R32: =J32*(MAX(1,ROUNDUP(J32/1,0)*1)*COSTE!$G$3) | S32: =SUM(T32:AU32) | V32: =J32*(10/5) | W32: =IF(J32=0,0,(((COSTE!$G$20/3)+(COSTE!$G$45*1)+(COSTE!$G$4/6)+(0.5)))/2) | X32: =(J32/4)*COSTE!$G$5 | Y32: =J32*((COSTE!$G$41*10)+(COSTE!$G$43*5)+(COSTE!$G$30 *1)+(COSTE!$G$34)+ 20) | Z32: =(6*COSTE!$G$4)*J32
A33: Muro | B33: Puerta | C33: Melamina | D33: Puerta Melamina a Medida + Maneta Codigo | E33: *New | J33: 0 | K33: 251 | L33: =IFERROR(ROUNDUP((Q33/J33)/0.5,0)*0.5,0) | M33: =IF(J33=0,J33*K33,J33*K33) | N33: =$N$46 | O33: =SUM(M33*N33)+M33 | P33: =SUM(O33-M33) | Q33: =R33+S33 | R33: =J33*(MAX(1,ROUNDUP(J33/1,0)*1)*COSTE!$G$3) | S33: =SUM(T33:AU33) | V33: =J33*(131/5) | W33: =IF(J33=0,0,(((COSTE!$G$20/3)+(COSTE!$G$45*1)+(COSTE!$G$4/6)+(0.5)))/2) | X33: =(J33/4)*COSTE!$G$5 | Y33: =J33*((COSTE!$G$41*10)+(COSTE!$G$43*5)+(COSTE!$G$30 *1)+(COSTE!$G$34)+ 20) | Z33: =(6*COSTE!$G$4)*J33
A34: Muro | B34: Puerta | C34: Melamina | D34: Puerta Melamina a Medida + Maneta Normal | E34: *New | J34: 0 | K34: 227 | L34: =IFERROR(ROUNDUP((Q34/J34)/0.5,0)*0.5,0) | M34: =IF(J34=0,J34*K34,J34*K34) | N34: =$N$46 | O34: =SUM(M34*N34)+M34 | P34: =SUM(O34-M34) | Q34: =R34+S34 | R34: =J34*(MAX(1,ROUNDUP(J34/1,0)*1)*COSTE!$G$3) | S34: =SUM(T34:AU34) | V34: =J34*(10/5) | W34: =IF(J34=0,0,(((COSTE!$G$20/3)+(COSTE!$G$45*1)+(COSTE!$G$4/6)+(0.5)))/2) | X34: =(J34/4)*COSTE!$G$5 | Y34: =J34*((COSTE!$G$41*10)+(COSTE!$G$43*5)+(COSTE!$G$30 *1)+(COSTE!$G$34)+ 20) | Z34: =(6*COSTE!$G$4)*J34
A35: Muro | B35: Puerta | C35: Cristal Alquiler | D35: Puerta (2,68m con Tarja) Alquiler | J35: 0 | K35: 209 | L35: =IFERROR(ROUNDUP((Q35/J35)/0.5,0)*0.5,0) | M35: =IF(J35=0,J35*K35,J35*K35) | N35: =$N$46 | O35: =SUM(M35*N35)+M35 | P35: =SUM(O35-M35) | Q35: =R35+S35 | R35: =J35*(MAX(1,ROUNDUP(J35/1,0)*1)*COSTE!$G$3) | S35: =SUM(T35:AU35) | T35: =(COSTE!G62/3)*J35 | V35: =J35*((200+150+150)/5) | X35: =(J35/4)*COSTE!$G$5
A36: FAMILIA | B36: SUB F. | C36: MATERIAL | D36: MURO - CRISTALES | E36: COMENTARIOS | F36: Largo | G36: Altura | I36: m2 | J36: UDS | K36: €/m2 | L36: €/Uni Real | M36: €/Empresa | N36: Markup % | O36: € TOTAL | P36: BEN.EMP | Q36: COSTE TOT | R36: Diseño 20m2/5h) | S36: COSTE MAT | T36: Cristal | U36: Cristal (/5) | V36: (8m2/h) T. Paletizacion | W36: Junquillos | X36: Canto | Y36: (20m2/h) Corte | Z36: (7m2/h) Cantear
A37: Muro | B37: Paredes | C37: Cristal | D37: Semimuro Compra | F37: 0 | G37: 0 | I37: =F37*G37 | J37: 0 | K37: 70 | L37: =IFERROR(ROUNDUP((Q37/I37)/0.5,0)*0.5,0) | M37: =IF(I37=0,J37*K37,I37*J37*K37) | N37: =$N$46 | O37: =SUM(M37*N37)+M37 | P37: =SUM(O37-M37) | Q37: =R37+S37 | R37: =J37*(MAX(1,ROUNDUP(I37/20,0)*5)*COSTE!$G$3) | S37: =SUM(T37:AU37) | T37: =((I37*6.49)+(I37*67.28)+(30))*J37 | V37: =(I37/8)*COSTE!$G$5 | W37: =(((F37*0.04)*4) +((G37*0.04)*4))*COSTE!$G$13 | X37: =((F37*8)+(G37*8))*COSTE!$G$49 | Y37: =((((F37*0.04)*4) +((G37*0.04)*4))/20)*COSTE!$G$4 | Z37: =((((F37*0.04)*4) +((G37*0.04)*4))/7)*COSTE!$G$4
A38: Muro | B38: Paredes | C38: Cristal Alquiler | D38: Pared (2,68m Altura) Alquiler | F38: 0 | G38: 0 | I38: =F38*G38 | J38: 0 | K38: 25 | L38: =IFERROR(ROUNDUP((Q38/I38)/0.5,0)*0.5,0) | M38: =IF(I38=0,J38*K38,I38*J38*K38) | N38: =$N$46 | O38: =SUM(M38*N38)+M38 | P38: =SUM(O38-M38) | Q38: =R38+S38 | R38: =J38*(MAX(1,ROUNDUP(I38/20,0)*5)*COSTE!$G$3) | S38: =SUM(U38:AU38) | U38: =(((I38*6.49)+(I38*67.28)+(30))/5)*J38 | V38: =(I38/8)*COSTE!$G$5 | W38: =(((F38*0.04)*4) +((G38*0.04)*4))*COSTE!$G$13 | X38: =((F38*8)+(G38*8))*COSTE!$G$49 | Y38: =((((F38*0.04)*4) +((G38*0.04)*4))/20)*COSTE!$G$4 | Z38: =((((F38*0.04)*4) +((G38*0.04)*4))/7)*COSTE!$G$4
A39: FAMILIA | B39: SUB F. | C39: MATERIAL | D39: MURO - CURVAS / REGATA LED / AISLANTE MURO | E39: COMENTARIOS | F39: Ancho | G39: Fondo | H39: Altura | I39: ml / m2 | J39: UDS | K39: €/ml m2 | L39: €/Uni Real | M39: €/Empresa | N39: Markup % | O39: € TOTAL | P39: BEN.EMP | Q39: COSTE TOT | R39: Diseño | S39: COSTE MAT | T39: (4 ml/h) T. Fabricación | U39: (2 ml/h) T. Fabricación | V39: Material | W39: (30m2/h) T. Paletizacion | X39: Palets | Y39: Tableros chopo | Z39: ( 20m2/h) Corte | AA39: Merma 20% | AB39: Estructura | AC39: Corte | AD39: Merma 20% | AE39: CNC | AF39: (2m2/h) T. Fabricación | AG39: (30m2/h) T. Paletizacion | AH39: Palets | AI39: Tornilleria
A40: Muro | B40: Curvas | C40: Chopo | D40: Para Pintar Chopo 5mm a 1 caras (Minimo 1m2 por tira) | F40: 0 | G40: 0 | H40: 0 | I40: =F40*G40 | J40: 0 | K40: 44 | L40: =IFERROR(ROUNDUP((Q40/I40)/0.5,0)*0.5,0) | M40: =IF(I40=0,J40*K40,I40*J40*K40) | N40: =$N$126 | O40: =SUM(M40*N40)+M40 | P40: =SUM(O40-M40) | Q40: =R40+S40 | R40: =J40*(MAX(1,ROUNDUP(I40/2,0)*1)*COSTE!$G$3) | S40: =SUM(T40:AU40) | Y40: =COSTE!$G$32*( (0.25*2*3.1415*F40)*H40) | Z40: =(( (0.25*2*3.1415*F40)*H40)/20)*COSTE!$G$4 | AA40: =Y40*20% | AB40: =COSTE!$G$20*((F40*G40)*H40)+((F40*H40)*((0.25*2*3.1415*F40)/0.5)) | AC40: =((F40*H40)*((0.25*2*3.1415*F40)*COSTE!$J$14)) | AD40: =AB40*20% | AE40: =(((F40*G40)*H40)/5)*25 | AF40: =(I40/1)*COSTE!$G$4 | AG40: =(I40/30)*COSTE!$G$5 | AH40: =ROUNDUP(I40/35,0)*((COSTE!$G$20/3)+(COSTE!$G$45*1)+(COSTE!$G$4/6)+(0.5)) | AI40: =I40*0.1
A41: Muro | B41: Curvas | C41: Chopo | D41: Para Pintar Chopo 5mm a 2 caras (Minimo 1m2 por tira) | F41: 0 | G41: 0 | H41: 0 | I41: =F41*G41 | J41: 0 | K41: 58 | L41: =IFERROR(ROUNDUP((Q41/I41)/0.5,0)*0.5,0) | M41: =IF(I41=0,J41*K41,I41*J41*K41) | N41: =$N$126 | O41: =SUM(M41*N41)+M41 | P41: =SUM(O41-M41) | Q41: =R41+S41 | R41: =J41*(MAX(1,ROUNDUP(I41/2,0)*1)*COSTE!$G$3) | S41: =SUM(T41:AU41) | Y41: =COSTE!$G$32*(( (0.25*2*3.1415*F41)*H41)*2) | Z41: =(( ((0.25*2*3.1415*F41)*H41)*2)/20)*COSTE!$G$4 | AA41: =Y41*20% | AB41: =COSTE!$G$20*((F41*G41)*H41)+((F41*H41)*((0.25*2*3.1415*F41)/0.5)) | AC41: =((F41*H41)*((0.25*2*3.1415*F41)*COSTE!$J$14)) | AD41: =AB41*20% | AE41: =(((F41*G41)*H41)/5)*25 | AF41: =(I41/0.75)*COSTE!$G$4 | AG41: =(I41/30)*COSTE!$G$5 | AH41: =ROUNDUP(I41/35,0)*((COSTE!$G$20/3)+(COSTE!$G$45*1)+(COSTE!$G$4/6)+(0.5)) | AI41: =I41*0.1
...

Sheet COSTE
J1: EXTRAS
A2: FAMILIA | B2: SUB.FAMILIA MATERIAL | C2: DESCRIPICON | D2: X (mm) | E2: Y (mm) | F2: Grosor (mm) | G2: PRECIO | H2: UNI | I2: PROVEEDOR | J2: € | K2: Concepto | L2: € | M2: Concepto | N2: € | O2: Concepto | P2: €/Tablero
A3: Personal | B3: Diseño | G3: =COMPARATIVA!G3 | H3: €/h | I3: ESWood
A4: Personal | B4: Fabricación | G4: =COMPARATIVA!G4 | H4: €/h | I4: ESWood | J4: 23.7 | K4: H. Extra | L4: 13.52 | M4: 1/2Dieta | N4: 67 | O4: Dieta completa
A5: Personal | B5: Montaje | G5: =COMPARATIVA!G5 | H5: €/h | I5: ESWood | J5: 23.7 | K5: H. Extra | L5: 13.52 | M5: 1/2Dieta | N5: 67 | O5: Dieta completa
A6: Personal | B6: Desmontaje | G6: =COMPARATIVA!G6 | H6: €/h | I6: ESWood | J6: 23.7 | K6: H. Extra | L6: 13.52 | M6: 1/2Dieta | N6: 67 | O6: Dieta completa
A7: Personal | B7: Externo | C7: Montaje / Desmontaje Externo al dia | G7: =COMPARATIVA!G7 | H7: dia | I7: German
A8: Personal | B8: Coordinador Externo | C8: Montaje / Desmontaje Coordinador Externo al dia | G8: =COMPARATIVA!G8 | H8: dia | I8: German
A9: Personal | B9: Externo+Herrameintas | G9: =COMPARATIVA!G9 | H9: dia
A10: Personal | B10: Externo+Herrameintas | G10: =COMPARATIVA!G10 | H10: dia
A11: CNC | B11: Corte | G11: =COMPARATIVA!G11 | H11: Tablero | I11: ESWood
A13: Tablero | B13: Mel. Blanca | C13: Melamina Blanco K-110 PE 2/c Sef 16 mm | D13: 2800 | E13: 2070 | F13: 16 | G13: =COMPARATIVA!G13 | H13: €/m2 | I13: =COMPARATIVA!I13 | J13: =COMPARATIVA!J13 | K13: Corte (+/-m2) | L13: =COMPARATIVA!L13 | M13: Cadel | P13: =((D13/1000)*(E13/1000))*G13
A14: Tablero | B14: Mel. Negra | C14: Melamina Negra U-190 VL 16 mm | D14: 2800 | E14: 2070 | F14: 16 | G14: =COMPARATIVA!G17 | H14: €/m2 | I14: =COMPARATIVA!I17 | J14: =COMPARATIVA!J17 | K14: Corte (+/-m2) | L14: =COMPARATIVA!L17 | M14: Cadel | P14: =((D14/1000)*(E14/1000))*G14
A15: Tablero | B15: Mel. Velvet | C15: Melamina Velvet Oak D-2693 MW 16 mm | D15: 2800 | E15: 2070 | F15: 16 | G15: 10 | H15: €/m2 | I15: Mausa | J15: =COMPARATIVA!J20 | K15: Corte (+/-m2) | L15: 1.35 | M15: Cadel | P15: =((D15/1000)*(E15/1000))*G15
A16: Tablero | B16: Mel. Niagra | C16: Melamina Niagara Oak D-2240 VL 16 mm | D16: 2800 | E16: 2070 | F16: 16 | G16: =COMPARATIVA!G21 | H16: €/m2 | I16: =COMPARATIVA!I21 | J16: =COMPARATIVA!J21 | K16: Corte (+/-m2) | L16: 1.35 | M16: Cadel | P16: =((D16/1000)*(E16/1000))*G16
A17: Tablero | B17: Mel. Epecial | D17: 2800 | E17: 2070 | F17: 16 | G17: 13 | H17: €/m2 | I17: =COMPARATIVA!I22 | J17: =COMPARATIVA!J22 | K17: Corte (+/-m2) | L17: 1.35 | M17: Cadel | P17: =((D17/1000)*(E17/1000))*G17
A18: Formica | B18: Blanca | C18: Formica HPL | F18: 0.8 | G18: 15 | H18: €/m2 | I18: Gabarro | P18: =((D18/1000)*(E18/1000))*G18
A20: Tablero | B20: Aglomerado | C20: Aglomerado 1a standard 16mm | D20: 2800 | E20: 2070 | F20: 16 | G20: =COMPARATIVA!G24 | H20: €/m2 | I20: =COMPARATIVA!I24 | J20: =COMPARATIVA!J24 | K20: Corte (+/-m2) | L20: =COMPARATIVA!L24 | M20: Cadel | P20: =((D20/1000)*(E20/1000))*G20
A21: Tablero | B21: Aglomerado | C21: Aglomerado 1a standard 19mm | D21: 2800 | E21: 2070 | F21: 19 | G21: =COMPARATIVA!G35 | H21: €/m2 | I21: =COMPARATIVA!I35 | J21: =COMPARATIVA!J35 | K21: Corte (+/-m2) | L21: =COMPARATIVA!L35 | M21: Cadel | P21: =((D21/1000)*(E21/1000))*G21
A23: Tablero | B23: MDF | C23: Tablex Blanco 5mm (Zocalo) | D23: 2440 | E23: 1220 | F23: 5 | G23: =COMPARATIVA!G37 | H23: €/m2 | I23: =COMPARATIVA!I37 | J23: =COMPARATIVA!J37 | K23: Corte (+/-m2) | P23: =((D23/1000)*(E23/1000))*G23
A24: Tablero | B24: MDF | C24: Tablex Negro 5mm (Zocalo) | D24: 2440 | E24: 1220 | F24: 5 | G24: =COMPARATIVA!G39 | H24: €/m2 | I24: =COMPARATIVA!I39 | J24: =COMPARATIVA!J39 | K24: Corte (+/-m2) | P24: =((D24/1000)*(E24/1000))*G24
A25: Tablero | B25: MDF | C25: MDF Standard 3 mm | D25: 2440 | E25: 1220 | F25: 3 | G25: =COMPARATIVA!G41 | H25: €/m2 | I25: =COMPARATIVA!I41 | J25: =COMPARATIVA!J41 | K25: Corte (+/-m2) | P25: =((D25/1000)*(E25/1000))*G25
A26: Tablero | B26: MDF | C26: MDF Standard 5 mm | D26: 2440 | E26: 1220 | F26: 5 | G26: =COMPARATIVA!G42 | H26: €/m2 | I26: =COMPARATIVA!I42 | J26: =COMPARATIVA!J42 | K26: Corte (+/-m2) | P26: =((D26/1000)*(E26/1000))*G26
A27: Tablero | B27: MDF | C27: MDF Standard 16 mm | D27: 3660 | E27: 2070 | F27: 16 | G27: =COMPARATIVA!G46 | H27: €/m2 | I27: =COMPARATIVA!I46 | J27: =COMPARATIVA!J46 | K27: Corte (+/-m2) | L27: =COMPARATIVA!L46 | M27: Cadel | P27: =((D27/1000)*(E27/1000))*G27
A28: Tablero | B28: MDF | C28: MDF Standard 19 mm | D28: 3660 | E28: 2070 | F28: 19 | G28: =COMPARATIVA!G51 | H28: €/m2 | I28: =COMPARATIVA!I51 | J28: =COMPARATIVA!J51 | K28: Corte (+/-m2) | L28: =COMPARATIVA!L51 | M28: Cadel | P28: =((D28/1000)*(E28/1000))*G28
A30: Tablero | B30: Chopo | C30: BB/BB | D30: 2500 | E30: 1220 | F30: 5 | G30: =COMPARATIVA!G57 | H30: €/m2 | I30: =COMPARATIVA!I57 | P30: =((D30/1000)*(E30/1000))*G30
A31: Tablero | B31: Chopo Felx. | C31: Tablero Fromager flexible 5 mm (mostrador) | D31: 1220 | E31: 2500 | F31: 5 | G31: =COMPARATIVA!G62 | H31: €/m2 | I31: =COMPARATIVA!I62 | P31: =((D31/1000)*(E31/1000))*G31
A32: Tablero | B32: Chopo Felx. | C32: Tablero Fromager flexible 5 mm (Columna) | D32: 1220 | E32: 2500 | F32: 5 | G32: =COMPARATIVA!G66 | H32: €/m2 | I32: =COMPARATIVA!I66 | P32: =((D32/1000)*(E32/1000))*G32
A33: Tablero | B33: Chopo | C33: BB/BB | D33: 2500 | E33: 1220 | F33: 10 | G33: =COMPARATIVA!G69 | H33: €/m2 | I33: =COMPARATIVA!I69 | P33: =((D33/1000)*(E33/1000))*G33
A34: Tablero | B34: Chopo | C34: BB/BB | D34: 2500 | E34: 1220 | F34: 15 | G34: =COMPARATIVA!G70 | H34: €/m2 | I34: =COMPARATIVA!I70 | P34: =((D34/1000)*(E34/1000))*G34
A36: Tablero | B36: OSB | C36: Tablero OSB 3 XOP | D36: 2500 | E36: 1250 | F36: 9 | G36: =COMPARATIVA!G75 | H36: €/m2 | I36: =COMPARATIVA!I75
A37: Tablero | B37: OSB | C37: Tablero OSB 3 XOP | D37: 2500 | E37: 1250 | F37: 15 | G37: =COMPARATIVA!G76 | H37: €/m2 | I37: =COMPARATIVA!I76
A38: Tablero | B38: OSB | C38: Tablero OSB 3 XOP | D38: 2500 | E38: 1250 | F38: 18 | G38: =COMPARATIVA!G77 | H38: €/m2 | I38: =COMPARATIVA!I77
A39: Tablero | B39: OSB | C39: Tablero OSB 3 XOP | D39: 2500 | E39: 1250 | F39: 22 | G39: =COMPARATIVA!G78 | H39: €/m2 | I39: =COMPARATIVA!I78
A41: Liston | B41: Pino | C41: Liston Flandes 45*21 | D41: 4500 | E41: 45 | F41: 21 | G41: =COMPARATIVA!G80 | H41: €/ml | I41: Forestal Vic
A42: Liston | B42: Pino | C42: Liston Flandes 45*45 | D42: 4500 | E42: 45 | F42: 45 | G42: =COMPARATIVA!G84 | H42: €/ml | I42: Forestal Vic
A43: Liston | B43: Pino | C43: Liston Flandes 45*70 | D43: 4500 | E43: 45 | F43: 70 | G43: =COMPARATIVA!G87 | H43: €/ml | I43: Forestal Vic
A44: Liston | B44: Pino | C44: Liston Flandes 20*90 | D44: 4200 | E44: 20 | F44: 90 | G44: =COMPARATIVA!G90 | H44: €/ml | I44: Forestal Vic
A45: Liston | B45: Aveto | C45: Liston Aveto 120*60 | D45: 6500 | E45: 120 | F45: 60 | G45: =COMPARATIVA!G92 | H45: €/ml | I45: Forestal Vic
A46: Liston | B46: Aveto | C46: Liston Aveto 120*120 | D46: 6500 | E46: 120 | F46: 120 | G46: =COMPARATIVA!G94 | H46: €/ml | I46: Forestal Vic
...

Sheet COMPARATIVA
J1: EXTRAS
A2: FAMILIA | B2: SUB.FAMILIA MATERIAL | C2: DESCRIPICON | D2: X (mm) | E2: Y (mm) | F2: Grosor (mm) | G2: PRECIO | H2: UNI | I2: PROVEEDOR | J2: € | K2: Concepto | L2: € | M2: Concepto | N2: € | O2: Concepto | P2: €/Tablero
A3: Personal | B3: Diseño | G3: 21.26 | H3: €/h | I3: ESWood
A4: Personal | B4: Fabricación | G4: 22.4 | H4: €/h | I4: ESWood | J4: 23.7 | K4: H. Extra | L4: 13.52 | M4: 1/2Dieta | N4: 67 | O4: Dieta completa
A5: Personal | B5: Montaje | G5: 19.23 | H5: €/h | I5: ESWood | J5: 23.7 | K5: H. Extra | L5: 13.52 | M5: 1/2Dieta | N5: 67 | O5: Dieta completa
A6: Personal | B6: Desmontaje | G6: 19.23 | H6: €/h | I6: ESWood | J6: 23.7 | K6: H. Extra | L6: 13.52 | M6: 1/2Dieta | N6: 67 | O6: Dieta completa
A7: Personal | B7: Externo | C7: Montaje / Desmontaje Externo al dia (German) | G7: 250 | H7: dia | I7: German
A8: Personal | B8: Coordinador Externo | C8: Montaje / Desmontaje Coordinador Externo al dia (German) | G8: 300 | H8: dia | I8: German
A9: Personal | B9: Externo+Herrameintas
A10: Personal | B10: Externo+Herrameintas
A11: CNC | B11: Corte | G11: 23 | H11: Tablero | I11: ESWood
A13: Tablero | B13: Mel. Blanca | C13: Melamina Blanca 8685 BS KRONOS | D13: 2800 | E13: 2070 | F13: 16 | G13: 4.79 | H13: €/m2 | I13: Closa | J13: 0.58 | K13: Corte (+/-m2) | L13: 1.35 | M13: Cadel (+/-m2) | P13: =((D13/1000)*(E13/1000))*G13
A14: Tablero | B14: Mel. Blanca | C14: Melamina Blanco K-110 PE 2/c Sef 16 mm | D14: 2800 | E14: 2070 | F14: 16 | G14: 6.35 | H14: €/m2 | I14: Mausa | J14: 1.98 | K14: Corte (+/-m2) | P14: =((D14/1000)*(E14/1000))*G14
A15: Tablero | B15: Mel. Branca | C15: Melamina Blanca TIZA W908 ST7 | D15: 2800 | E15: 2070 | F15: 16 | G15: 5.35 | H15: €/m2 | I15: Albertch | N15: 5.16 | O15: Paquete | P15: =((D15/1000)*(E15/1000))*G15
A16: Tablero | B16: Mel. Blanca | C16: Melamina Blanca 8685 BS KRONOS | D16: 2800 | E16: 2070 | F16: 16 | G16: 5.07 | H16: €/m2 | I16: Albertch | N16: 4.9 | O16: Paquete | P16: =((D16/1000)*(E16/1000))*G16
A17: Tablero | B17: Mel. Negra | C17: Melamina Negra 16mm | D17: 2800 | E17: 2070 | F17: 16 | G17: 4.79 | H17: €/m2 | I17: Closa | J17: 0.58 | K17: Corte (+/-m2) | L17: 1.35 | M17: Cadel (+/-m2) | P17: =((D17/1000)*(E17/1000))*G17
A18: Tablero | B18: Mel. Negra | C18: Melamina Negra U-190 VL 16 mm | D18: 2800 | E18: 2070 | F18: 16 | H18: €/m2 | I18: Mausa | J18: 1.98 | K18: Corte (+/-m2) | P18: =((D18/1000)*(E18/1000))*G18
A19: Tablero | B19: Mel. Negra | C19: Melamina Negra 0190 BS KRONOS | D19: 2850 | E19: 2100 | F19: 16 | G19: 5.07 | H19: €/m2 | I19: Albertch | N19: 4.9 | O19: Paquete | P19: =((D19/1000)*(E19/1000))*G19
A20: Tablero | B20: Mel. Velvet | C20: Melamina Velvet Oak D-2693 MW 16 mm | D20: 2800 | E20: 2070 | F20: 16 | H20: €/m2 | I20: Mausa | J20: 1.98 | K20: Corte (+/-m2) | P20: =((D20/1000)*(E20/1000))*G20
A21: Tablero | B21: Mel. Niagra | C21: Melamina Niagara Oak D-2240 VL 16 mm | D21: 2800 | E21: 2070 | F21: 16 | G21: 9.8 | H21: €/m2 | I21: Mausa | J21: 1.98 | K21: Corte (+/-m2) | P21: =((D21/1000)*(E21/1000))*G21
A22: Tablero | B22: Mel. Papaya | C22: Melamina Monument Papaya Luxor 19 mm | D22: 2850 | E22: 2100 | F22: 19 | H22: €/m2 | I22: Mausa | J22: 1.98 | K22: Corte (+/-m2) | P22: =((D22/1000)*(E22/1000))*G22
A24: Tablero | B24: Aglomerado | C24: Aglomerado 1a standard 16mm | D24: 2800 | E24: 2070 | F24: 16 | G24: 3.78 | H24: €/m2 | I24: Closa | J24: 0.58 | K24: Corte (+/-m2) | L24: 1.35 | M24: Cadel (+/-m2) | P24: =((D24/1000)*(E24/1000))*G24
A25: Tablero | B25: Aglomerado | C25: Aglomerado 1a standard 16mm | D25: 2800 | E25: 2070 | F25: 16 | G25: 3.69 | H25: €/m2 | I25: Albaertch | N25: 3.57 | O25: Paquete | P25: =((D25/1000)*(E25/1000))*G25
A26: Tablero | B26: Aglomerado | C26: Aglomerado 1a standard 16mm | D26: 2800 | E26: 2070 | F26: 16 | G26: 4.02 | H26: €/m2 | I26: Gabarro | J26: =425.35/235 | K26: Corte (+/-m2) | L26: =428.61/296 | M26: Cadel (+/-m2) | P26: =((D26/1000)*(E26/1000))*G26
A27: Tablero | B27: Aglomerado | C27: Aglomerado 1a standard 16mm | D27: 2800 | E27: 2070 | F27: 16 | G27: 4.65 | H27: €/m2 | I27: Mausa | J27: 1.98 | K27: Corte (+/-m2) | P27: =((D27/1000)*(E27/1000))*G27
A28: Tablero | B28: Aglomerado | C28: Aglomerado 1a standard 16mm | D28: 3660 | E28: 2070 | F28: 16 | G28: 3.78 | H28: €/m2 | I28: Closa | J28: 0.58 | K28: Corte (+/-m2) | L28: 1.35 | M28: Cadel (+/-m2) | P28: =((D28/1000)*(E28/1000))*G28
A29: Tablero | B29: Aglomerado | C29: Aglomerado 1a standard 16mm | D29: 3660 | E29: 2070 | F29: 16 | G29: 4.02 | H29: €/m2 | I29: Gabarro | J29: =425.35/235 | K29: Corte (+/-m2) | L29: =428.61/296 | M29: Cadel (+/-m2) | P29: =((D29/1000)*(E29/1000))*G29
A30: Tablero | B30: Aglomerado | C30: Aglomerado 1a standard 16mm | D30: 3660 | E30: 2070 | F30: 16 | G30: 4.65 | H30: €/m2 | I30: Mausa | J30: 1.98 | K30: Corte (+/-m2) | P30: =((D30/1000)*(E30/1000))*G30
A31: Tablero | B31: Aglomerado | C31: Aglomerado 1a standard 16mm | D31: 3050 | E31: 2070 | F31: 16 | G31: 4.61 | H31: €/m2 | I31: Gabarro | J31: =425.35/235 | K31: Corte (+/-m2) | L31: =428.61/296 | M31: Cadel (+/-m2) | P31: =((D31/1000)*(E31/1000))*G31
A32: Tablero | B32: Aglomerado | C32: Aglomerado 1a standard 16mm | D32: 3050 | E32: 2070 | F32: 16 | G32: 3.69 | H32: €/m2 | I32: Albaertch | N32: 3.57 | O32: Paquete | P32: =((D32/1000)*(E32/1000))*G32
A33: Tablero | B33: Aglomerado | C33: Aglomerado 1a standard 16mm | D33: 4000 | E33: 2070 | F33: 16 | G33: 4.61 | H33: €/m2 | I33: Gabarro | J33: =425.35/235 | K33: Corte (+/-m2) | L33: =428.61/296 | M33: Cadel (+/-m2) | P33: =((D33/1000)*(E33/1000))*G33
A34: Tablero | B34: Aglomerado | C34: Aglomerado 1a standard 16mm | D34: 4000 | E34: 2070 | F34: 16 | G34: 3.69 | H34: €/m2 | I34: Albaertch | N34: 3.57 | O34: Paquete | P34: =((D34/1000)*(E34/1000))*G34
A35: Tablero | B35: Aglomerado | C35: Aglomerado 1a standard 19mm | D35: 2800 | E35: 2070 | F35: 19 | G35: 4.53 | H35: €/m2 | I35: Closa | J35: 0.58 | K35: Corte (+/-m2) | L35: 1.35 | M35: Cadel (+/-m2) | P35: =((D35/1000)*(E35/1000))*G35
A37: Tablero | B37: MDF Blanco | C37: MDF Lacado Blanco 1/Cara | D37: 244 | E37: 122 | F37: 5 | G37: 5.07 | H37: €/m2 | I37: Closa | J37: 0.58 | K37: Corte (+/- m2) | P37: =((D37/1000)*(E37/1000))*G37
A38: Tablero | B38: MDF | C38: Tablex Blanco 5mm (Zocalo) | D38: 2440 | E38: 1220 | F38: 5 | H38: €/m2 | I38: Mausa | P38: =((D38/1000)*(E38/1000))*G38
A39: Tablero | B39: MDF | C39: Tablex Negro 5mm (Zocalo) | D39: 2440 | E39: 1220 | F39: 5 | G39: 7 | H39: €/m2 | I39: Closa | J39: 0.58 | K39: Corte (+/- m2) | P39: =((D39/1000)*(E39/1000))*G39
A40: Tablero | B40: MDF | C40: Tablex Negro 5mm (Zocalo) | D40: 2440 | E40: 1220 | F40: 5 | H40: €/m2 | I40: Mausa | P40: =((D40/1000)*(E40/1000))*G40
A41: Tablero | B41: MDF | C41: MDF Standard 3 mm | D41: 2440 | E41: 1220 | F41: 3 | G41: 3 | H41: €/m2 | I41: Closa | J41: 0.58 | K41: Corte (+/-m2) | P41: =((D41/1000)*(E41/1000))*G41
A42: Tablero | B42: MDF | C42: MDF Standard 5 mm | D42: 2440 | E42: 1220 | F42: 5 | G42: 2.4 | H42: €/m2 | I42: Closa | J42: 0.58 | K42: Corte (+/-m2) | P42: =((D42/1000)*(E42/1000))*G42
A43: Tablero | B43: MDF | C43: MDF Standard 5 mm | D43: 2440 | E43: 1220 | F43: 5 | G43: 3.05 | H43: €/m2 | I43: Gabarro | J43: =425.35/235 | K43: Corte (+/-m2) | L43: =428.61/296 | M43: Cadel (+/-m2) | P43: =((D43/1000)*(E43/1000))*G43
...

Sheet CALCULADORA 
A1: CALCULAR €/m2 DE TABLERO
A2: Largo m | B2: Ancho m | C2: m2 | D2: € Tablero | E2: €/m2
A3: 2.8 | B3: 2.07 | C3: =A3*B3 | D3: 106.2 | E3: =D3/C3 | G3: 6.89 | H3: 33 | I3: 4.61
A5: CALCULAR €/m2 DE CORTE
A6: Tableros | B6: Largo m | C6: Ancho m | D6: m2 | E6: m2 TOT | F6: € TOT Corte | G6: €/m2
A7: 8 | B7: 2.44 | C7: 1.22 | D7: =B7*C7 | E7: =D7*A7 | F7: 25 | G7: =F7/E7
A9: CALCULAR € TABLERO
A10: Largo m | B10: Ancho m | C10: m2 | D10: € Tablero | E10: €/m2
A11: 2.8 | B11: 2.07 | C11: =A11*B11 | D11: =C11*E11 | E11: 5.07

Sheet README_IMPORT
A1: ARCHIVO SEGURO PARA IMPORTACIÓN
A2: Este libro conserva intactas las hojas originales y añade hojas planas para lectura segura por scripts o bases de datos.
A3: Hojas originales conservadas | B3: PRESUPUESTO, COSTE, COMPARATIVA, CALCULADORA
A4: Hoja recomendada para tu app | B4: CATALOGO_IMPORT
A5: Qué contiene CATALOGO_IMPORT | B5: Una fila por partida/opción del PRESUPUESTO, sin celdas combinadas y con columnas fijas.
A6: Precio recomendado para importar | B6: unit_price_base
A7: Clave de familia recomendada | B7: family_key
A8: Clave única de item recomendada | B8: item_key
A9: Trazabilidad | B9: Cada fila guarda source_sheet y source_row para volver al origen exacto.
A10: Notas | B10: Las fórmulas del original se mantienen en sus hojas. Las hojas *_IMPORT usan valores planos para que la lectura sea robusta.

Sheet CATALOGO_IMPORT
A1: CATÁLOGO NORMALIZADO DESDE PRESUPUESTO
A2: source_sheet | B2: source_row | C2: section_header_row | D2: section_title | E2: family_key | F2: item_key | G2: family | H2: subfamily | I2: material | J2: item_name | K2: comments | L2: input1_label | M2: input2_label | N2: input3_label | O2: measure_unit | P2: quantity_label | Q2: price_label | R2: unit_price_base | S2: unit_price_raw | T2: measure_current | U2: measure_formula | V2: qty_current | W2: real_price_current | X2: real_price_formula | Y2: company_cost_current | Z2: company_cost_formula | AA2: markup_current | AB2: markup_formula | AC2: total_current | AD2: total_formula
A3: PRESUPUESTO | B3: 5 | C3: 4 | D3: TARIMA | E3: tarima | F3: tarima_suelo_aglomerado_reciclado_tarima_con_moqueta | G3: Tarima | H3: Suelo | I3: Aglomerado Reciclado | J3: Tarima con Moqueta | L3: Largo | M3: Ancho | O3: m2 | P3: UDS | Q3: €/m2 | R3: 7.77 | S3: 7.77 | T3: 0 | U3: =F5*G5 | V3: 0 | W3: 0 | X3: =IFERROR(ROUNDUP((Q5/I5)/0.5,0)*0.5,0) | Y3: 0 | Z3: =IF(I5=0,J5*K5,I5*J5*K5) | AA3: 1 | AB3: =$N$14 | AC3: 0 | AD3: =SUM(M5*N5)+M5
A4: PRESUPUESTO | B4: 6 | C4: 4 | D4: TARIMA | E4: tarima | F4: tarima_suelo_melamina_reciclado_tarima_melamina_reciclada | G4: Tarima | H4: Suelo | I4: Melamina Reciclado | J4: Tarima Melamina Reciclada | L4: Largo | M4: Ancho | O4: m2 | P4: UDS | Q4: €/m2 | R4: 22 | S4: 22 | T4: 0 | U4: =F6*G6 | V4: 0 | W4: 0 | X4: =IFERROR(ROUNDUP((Q6/I6)/0.5,0)*0.5,0) | Y4: 0 | Z4: =IF(I6=0,J6*K6,I6*J6*K6) | AA4: 1 | AB4: =$N$14 | AC4: 0 | AD4: =SUM(M6*N6)+M6
A5: PRESUPUESTO | B5: 7 | C5: 4 | D5: TARIMA | E5: tarima | F5: tarima_suelo_melamina_tarima_melamina_nueva | G5: Tarima | H5: Suelo | I5: Melamina | J5: Tarima Melamina Nueva | K5: *New | L5: Largo | M5: Ancho | O5: m2 | P5: UDS | Q5: €/m2 | R5: 30 | S5: 30 | T5: 0 | U5: =F7*G7 | V5: 0 | W5: 0 | X5: =IFERROR(ROUNDUP((Q7/I7)/0.5,0)*0.5,0) | Y5: 0 | Z5: =IF(I7=0,J7*K7,I7*J7*K7) | AA5: 1 | AB5: =$N$14 | AC5: 0 | AD5: =SUM(M7*N7)+M7
A6: PRESUPUESTO | B6: 8 | C6: 4 | D6: TARIMA | E6: tarima | F6: tarima_suelo_melamina_especial_tarima_melamina_especial | G6: Tarima | H6: Suelo | I6: Melamina Especial | J6: Tarima Melamina Especial | L6: Largo | M6: Ancho | O6: m2 | P6: UDS | Q6: €/m2 | R6: 32.58 | S6: 32.58 | T6: 0 | U6: =F8*G8 | V6: 0 | W6: 0 | X6: =IFERROR(ROUNDUP((Q8/I8)/0.5,0)*0.5,0) | Y6: 0 | Z6: =IF(I8=0,J8*K8,I8*J8*K8) | AA6: 1 | AB6: =$N$14 | AC6: 0 | AD6: =SUM(M8*N8)+M8
A7: PRESUPUESTO | B7: 10 | C7: 9 | D7: TARIMA - RAMPA | E7: tarima | F7: tarima_rampa_tarima_rampa_estandar_1x1 | G7: Tarima | H7: Rampa | I7: Tarima | J7: Rampa (Estandar 1x1) | K7: *El coste rampa lo pondria siempre igual por m2 ya que el valor del material esta en la tarima | L7: Fondo | M7: Ancho | O7: m2 | P7: UDS | Q7: €/m2 | R7: 28 | S7: 28 | T7: 0 | U7: =F10*G10 | V7: 0 | W7: 0 | X7: =IFERROR(ROUNDUP((Q10/I10)/0.5,0)*0.5,0) | Y7: 0 | Z7: =IF(I10=0,J10*K10,I10*J10*K10) | AA7: 1 | AB7: =$N$14 | AC7: 0 | AD7: =SUM(M10*N10)+M10
A8: PRESUPUESTO | B8: 12 | C8: 11 | D8: TARIMA - REGATA LED | E8: tarima | F8: tarima_proceso_regata_regata_led_recta | G8: Tarima | H8: Proceso | I8: Regata | J8: Regata Led Recta | O8: ml | P8: UDS | Q8: €/ml | R8: 5 | S8: 5 | T8: 0 | V8: 0 | W8: 0 | X8: =IFERROR(ROUNDUP((Q12/I12)/0.5,0)*0.5,0) | Y8: 0 | Z8: =IF(I12=0,J12*K12,I12*J12*K12) | AA8: 1 | AB8: =$N$14 | AC8: 0 | AD8: =SUM(M12*N12)+M12
A9: PRESUPUESTO | B9: 13 | C9: 11 | D9: TARIMA - REGATA LED | E9: tarima | F9: tarima_proceso_regata_regata_led_diagonal_o_curva | G9: Tarima | H9: Proceso | I9: Regata | J9: Regata Led Diagonal o Curva | O9: ml | P9: UDS | Q9: €/ml | R9: 10 | S9: 10 | T9: 0 | V9: 0 | W9: 0 | X9: =IFERROR(ROUNDUP((Q13/I13)/0.5,0)*0.5,0) | Y9: 0 | Z9: =IF(I13=0,J13*K13,I13*J13*K13) | AA9: 1 | AB9: =$N$14 | AC9: 0 | AD9: =SUM(M13*N13)+M13
A10: PRESUPUESTO | B10: 16 | C10: 15 | D10: MURO | E10: muro | F10: muro_paredes_aglomerado_1_cara_grosor_estandar_0_1m_altura_2_75m | G10: Muro | H10: Paredes | I10: Aglomerado | J10: 1 Cara (Grosor Estandar 0,1m / Altura 2,75m) | K10: *El grosor se pone en el excel | L10: Largo | M10: Altura | N10: Grosor | O10: m2 | P10: UDS | Q10: €/m2 | R10: 14 | S10: 14 | T10: 0 | U10: =F16*G16 | V10: 0 | W10: 0 | X10: =IFERROR(ROUNDUP((Q16/I16)/0.5,0)*0.5,0) | Y10: 0 | Z10: =IF(I16=0,J16*K16,I16*J16*K16) | AA10: 1 | AB10: =$N$46 | AC10: 0 | AD10: =SUM(M16*N16)+M16
A11: PRESUPUESTO | B11: 17 | C11: 15 | D11: MURO | E11: muro | F11: muro_paredes_aglomerado_2_cara_grosor_estandar_0_1m_altura_2_75m | G11: Muro | H11: Paredes | I11: Aglomerado | J11: 2 Cara (Grosor Estandar 0,1m / Altura 2,75m) | K11: *El grosor se pone en el excel | L11: Largo | M11: Altura | N11: Grosor | O11: m2 | P11: UDS | Q11: €/m2 | R11: 22 | S11: 22 | T11: 0 | U11: =F17*G17 | V11: 0 | W11: 0 | X11: =IFERROR(ROUNDUP((Q17/I17)/0.5,0)*0.5,0) | Y11: 0 | Z11: =IF(I17=0,J17*K17,I17*J17*K17) | AA11: 1 | AB11: =$N$46 | AC11: 0 | AD11: =SUM(M17*N17)+M17
A12: PRESUPUESTO | B12: 18 | C12: 15 | D12: MURO | E12: muro | F12: muro_paredes_mdf_1_cara_grosor_estandar_0_1m_altura_2_75m | G12: Muro | H12: Paredes | I12: MDF | J12: 1 Cara (Grosor Estandar 0,1m / Altura 2,75m) | K12: *El grosor se pone en el excel | L12: Largo | M12: Altura | N12: Grosor | O12: m2 | P12: UDS | Q12: €/m2 | R12: 21 | S12: 21 | T12: 0 | U12: =F18*G18 | V12: 0 | W12: 0 | X12: =IFERROR(ROUNDUP((Q18/I18)/0.5,0)*0.5,0) | Y12: 0 | Z12: =IF(I18=0,J18*K18,I18*J18*K18) | AA12: 1 | AB12: =$N$46 | AC12: 0 | AD12: =SUM(M18*N18)+M18
A13: PRESUPUESTO | B13: 19 | C13: 15 | D13: MURO | E13: muro | F13: muro_paredes_mdf_2_cara_grosor_estandar_0_1m_altura_2_75m | G13: Muro | H13: Paredes | I13: MDF | J13: 2 Cara (Grosor Estandar 0,1m/ Altura 2,75m) | K13: *El grosor se pone en el excel | L13: Largo | M13: Altura | N13: Grosor | O13: m2 | P13: UDS | Q13: €/m2 | R13: 34 | S13: 34 | T13: 0 | U13: =F19*G19 | V13: 0 | W13: 0 | X13: =IFERROR(ROUNDUP((Q19/I19)/0.5,0)*0.5,0) | Y13: 0 | Z13: =IF(I19=0,J19*K19,I19*J19*K19) | AA13: 1 | AB13: =$N$46 | AC13: 0 | AD13: =SUM(M19*N19)+M19
A14: PRESUPUESTO | B14: 20 | C14: 15 | D14: MURO | E14: muro | F14: muro_paredes_melamina_1_cara_grosor_estandar_0_1m_altura_2_75m | G14: Muro | H14: Paredes | I14: Melamina | J14: 1 Cara (Grosor Estandar 0,1m / Altura 2,75m) | K14: *El grosor se pone en el excel | L14: Largo | M14: Altura | N14: Grosor | O14: m2 | P14: UDS | Q14: €/m2 | R14: 15 | S14: 15 | T14: 0 | U14: =F20*G20 | V14: 0 | W14: 0 | X14: =IFERROR(ROUNDUP((Q20/I20)/0.5,0)*0.5,0) | Y14: 0 | Z14: =IF(I20=0,J20*K20,I20*J20*K20) | AA14: 1 | AB14: =$N$46 | AC14: 0 | AD14: =SUM(M20*N20)+M20
A15: PRESUPUESTO | B15: 21 | C15: 15 | D15: MURO | E15: muro | F15: muro_paredes_melamina_2_cara_grosor_estandar_0_1m_altura_2_75m | G15: Muro | H15: Paredes | I15: Melamina | J15: 2 Cara (Grosor Estandar 0,1m / Altura 2,75m) | K15: *El grosor se pone en el excel | L15: Largo | M15: Altura | N15: Grosor | O15: m2 | P15: UDS | Q15: €/m2 | R15: 25 | S15: 25 | T15: 0 | U15: =F21*G21 | V15: 0 | W15: 0 | X15: =IFERROR(ROUNDUP((Q21/I21)/0.5,0)*0.5,0) | Y15: 0 | Z15: =IF(I21=0,J21*K21,I21*J21*K21) | AA15: 1 | AB15: =$N$46 | AC15: 0 | AD15: =SUM(M21*N21)+M21
A16: PRESUPUESTO | B16: 22 | C16: 15 | D16: MURO | E16: muro | F16: muro_paredes_melamina_especial_chopo_1_cara_grosor_estandar_0_1m_altura_2_75m | G16: Muro | H16: Paredes | I16: Melamina Especial / Chopo | J16: 1 Cara (Grosor Estandar 0,1m/ Altura 2,75m) | K16: *El grosor se pone en el excel | L16: Largo | M16: Altura | N16: Grosor | O16: m2 | P16: UDS | Q16: €/m2 | R16: 21 | S16: 21 | T16: 0 | U16: =F22*G22 | V16: 0 | W16: 0 | X16: =IFERROR(ROUNDUP((Q22/I22)/0.5,0)*0.5,0) | Y16: 0 | Z16: =IF(I22=0,J22*K22,I22*J22*K22) | AA16: 1 | AB16: =$N$46 | AC16: 0 | AD16: =SUM(M22*N22)+M22
A17: PRESUPUESTO | B17: 23 | C17: 15 | D17: MURO | E17: muro | F17: muro_paredes_melamina_especial_chopo_2_cara_grosor_estandar_0_1m_altura_2_75m | G17: Muro | H17: Paredes | I17: Melamina Especial / Chopo | J17: 2 Cara (Grosor Estandar 0,1m/ Altura 2,75m) | K17: *El grosor se pone en el excel | L17: Largo | M17: Altura | N17: Grosor | O17: m2 | P17: UDS | Q17: €/m2 | R17: 36 | S17: 36 | T17: 0 | U17: =F23*G23 | V17: 0 | W17: 0 | X17: =IFERROR(ROUNDUP((Q23/I23)/0.5,0)*0.5,0) | Y17: 0 | Z17: =IF(I23=0,J23*K23,I23*J23*K23) | AA17: 1 | AB17: =$N$46 | AC17: 0 | AD17: =SUM(M23*N23)+M23
A18: PRESUPUESTO | B18: 25 | C18: 24 | D18: MURO - BMATRIX | E18: muro | F18: muro_paredes_bmatrix_alquiler_muro_bmatrix | G18: Muro | H18: Paredes | I18: Bmatrix | J18: Alquiler Muro Bmatrix | K18: *Modificar coste?? | L18: Largo | M18: Altura | N18: Grosor | O18: m2 | P18: UDS | Q18: €/m2 | R18: 50 | S18: 50 | T18: 0 | U18: =F25*G25 | V18: 0 | W18: 0 | X18: =IFERROR(ROUNDUP((Q25/I25)/0.5,0)*0.5,0) | Y18: 0 | Z18: =IF(I25=0,J25*K25,I25*J25*K25) | AA18: 1 | AB18: =$N$46 | AC18: 0 | AD18: =SUM(M25*N25)+M25
A19: PRESUPUESTO | B19: 27 | C19: 26 | D19: MURO - PUERTA | E19: muro | F19: muro_puerta_pintar_puerta_maneta_codigo | G19: Muro | H19: Puerta | I19: Pintar | J19: Puerta + Maneta Codigo | P19: UDS | Q19: €/Uni | R19: 85 | S19: 85 | V19: 0 | W19: 0 | X19: =IFERROR(ROUNDUP((Q27/J27)/0.5,0)*0.5,0) | Y19: 0 | Z19: =IF(J27=0,J27*K27,J27*K27) | AA19: 1 | AB19: =$N$46 | AC19: 0 | AD19: =SUM(M27*N27)+M27
A20: PRESUPUESTO | B20: 28 | C20: 26 | D20: MURO - PUERTA | E20: muro | F20: muro_puerta_pintar_puerta_maneta_normal | G20: Muro | H20: Puerta | I20: Pintar | J20: Puerta + Maneta Normal | P20: UDS | Q20: €/Uni | R20: 65 | S20: 65 | V20: 0 | W20: 0 | X20: =IFERROR(ROUNDUP((Q28/J28)/0.5,0)*0.5,0) | Y20: 0 | Z20: =IF(J28=0,J28*K28,J28*K28) | AA20: 1 | AB20: =$N$46 | AC20: 0 | AD20: =SUM(M28*N28)+M28
A21: PRESUPUESTO | B21: 29 | C21: 26 | D21: MURO - PUERTA | E21: muro | F21: muro_puerta_blanco_lacado_puerta_melamina_1_cara_maneta_codigo | G21: Muro | H21: Puerta | I21: Blanco Lacado | J21: Puerta Melamina 1 cara + Maneta Codigo | P21: UDS | Q21: €/Uni | R21: 300 | S21: 300 | V21: 0 | W21: 0 | X21: =IFERROR(ROUNDUP((Q29/J29)/0.5,0)*0.5,0) | Y21: 0 | Z21: =IF(J29=0,J29*K29,J29*K29) | AA21: 1 | AB21: =$N$46 | AC21: 0 | AD21: =SUM(M29*N29)+M29
A22: PRESUPUESTO | B22: 30 | C22: 26 | D22: MURO - PUERTA | E22: muro | F22: muro_puerta_blanco_lacado_puerta_melamina_1_cara_maneta_normal | G22: Muro | H22: Puerta | I22: Blanco Lacado | J22: Puerta Melamina 1 cara + Maneta Normal | P22: UDS | Q22: €/Uni | R22: 300 | S22: 300 | V22: 0 | W22: 0 | X22: =IFERROR(ROUNDUP((Q30/J30)/0.5,0)*0.5,0) | Y22: 0 | Z22: =IF(J30=0,J30*K30,J30*K30) | AA22: 1 | AB22: =$N$46 | AC22: 0 | AD22: =SUM(M30*N30)+M30
A23: PRESUPUESTO | B23: 31 | C23: 26 | D23: MURO - PUERTA | E23: muro | F23: muro_puerta_chopo_puerta_para_pintar_a_medida_maneta_codigo | G23: Muro | H23: Puerta | I23: Chopo | J23: Puerta para Pintar a Medida + Maneta Codigo | K23: *New | P23: UDS | Q23: €/Uni | R23: 257 | S23: 257 | V23: 0 | W23: 0 | X23: =IFERROR(ROUNDUP((Q31/J31)/0.5,0)*0.5,0) | Y23: 0 | Z23: =IF(J31=0,J31*K31,J31*K31) | AA23: 1 | AB23: =$N$46 | AC23: 0 | AD23: =SUM(M31*N31)+M31
A24: PRESUPUESTO | B24: 32 | C24: 26 | D24: MURO - PUERTA | E24: muro | F24: muro_puerta_chopo_puerta_para_pintar_a_medida_maneta_normal | G24: Muro | H24: Puerta | I24: Chopo | J24: Puerta para Pintar a Medida + Maneta Normal | K24: *New | P24: UDS | Q24: €/Uni | R24: 233 | S24: 233 | V24: 0 | W24: 0 | X24: =IFERROR(ROUNDUP((Q32/J32)/0.5,0)*0.5,0) | Y24: 0 | Z24: =IF(J32=0,J32*K32,J32*K32) | AA24: 1 | AB24: =$N$46 | AC24: 0 | AD24: =SUM(M32*N32)+M32
A25: PRESUPUESTO | B25: 33 | C25: 26 | D25: MURO - PUERTA | E25: muro | F25: muro_puerta_melamina_puerta_melamina_a_medida_maneta_codigo | G25: Muro | H25: Puerta | I25: Melamina | J25: Puerta Melamina a Medida + Maneta Codigo | K25: *New | P25: UDS | Q25: €/Uni | R25: 251 | S25: 251 | V25: 0 | W25: 0 | X25: =IFERROR(ROUNDUP((Q33/J33)/0.5,0)*0.5,0) | Y25: 0 | Z25: =IF(J33=0,J33*K33,J33*K33) | AA25: 1 | AB25: =$N$46 | AC25: 0 | AD25: =SUM(M33*N33)+M33
A26: PRESUPUESTO | B26: 34 | C26: 26 | D26: MURO - PUERTA | E26: muro | F26: muro_puerta_melamina_puerta_melamina_a_medida_maneta_normal | G26: Muro | H26: Puerta | I26: Melamina | J26: Puerta Melamina a Medida + Maneta Normal | K26: *New | P26: UDS | Q26: €/Uni | R26: 227 | S26: 227 | V26: 0 | W26: 0 | X26: =IFERROR(ROUNDUP((Q34/J34)/0.5,0)*0.5,0) | Y26: 0 | Z26: =IF(J34=0,J34*K34,J34*K34) | AA26: 1 | AB26: =$N$46 | AC26: 0 | AD26: =SUM(M34*N34)+M34
A27: PRESUPUESTO | B27: 35 | C27: 26 | D27: MURO - PUERTA | E27: muro | F27: muro_puerta_cristal_alquiler_puerta_2_68m_con_tarja_alquiler | G27: Muro | H27: Puerta | I27: Cristal Alquiler | J27: Puerta (2,68m con Tarja) Alquiler | P27: UDS | Q27: €/Uni | R27: 209 | S27: 209 | V27: 0 | W27: 0 | X27: =IFERROR(ROUNDUP((Q35/J35)/0.5,0)*0.5,0) | Y27: 0 | Z27: =IF(J35=0,J35*K35,J35*K35) | AA27: 1 | AB27: =$N$46 | AC27: 0 | AD27: =SUM(M35*N35)+M35
A28: PRESUPUESTO | B28: 37 | C28: 36 | D28: MURO - CRISTALES | E28: muro | F28: muro_paredes_cristal_semimuro_compra | G28: Muro | H28: Paredes | I28: Cristal | J28: Semimuro Compra | L28: Largo | M28: Altura | O28: m2 | P28: UDS | Q28: €/m2 | R28: 70 | S28: 70 | T28: 0 | U28: =F37*G37 | V28: 0 | W28: 0 | X28: =IFERROR(ROUNDUP((Q37/I37)/0.5,0)*0.5,0) | Y28: 0 | Z28: =IF(I37=0,J37*K37,I37*J37*K37) | AA28: 1 | AB28: =$N$46 | AC28: 0 | AD28: =SUM(M37*N37)+M37
A29: PRESUPUESTO | B29: 38 | C29: 36 | D29: MURO - CRISTALES | E29: muro | F29: muro_paredes_cristal_alquiler_pared_2_68m_altura_alquiler | G29: Muro | H29: Paredes | I29: Cristal Alquiler | J29: Pared (2,68m Altura) Alquiler | L29: Largo | M29: Altura | O29: m2 | P29: UDS | Q29: €/m2 | R29: 25 | S29: 25 | T29: 0 | U29: =F38*G38 | V29: 0 | W29: 0 | X29: =IFERROR(ROUNDUP((Q38/I38)/0.5,0)*0.5,0) | Y29: 0 | Z29: =IF(I38=0,J38*K38,I38*J38*K38) | AA29: 1 | AB29: =$N$46 | AC29: 0 | AD29: =SUM(M38*N38)+M38
A30: PRESUPUESTO | B30: 40 | C30: 39 | D30: MURO - CURVAS / REGATA LED / AISLANTE MURO | E30: muro | F30: muro_curvas_chopo_para_pintar_chopo_5mm_a_1_caras_minimo_1m2_por_tira | G30: Muro | H30: Curvas | I30: Chopo | J30: Para Pintar Chopo 5mm a 1 caras (Minimo 1m2 por tira) | L30: Ancho | M30: Fondo | N30: Altura | O30: ml / m2 | P30: UDS | Q30: €/ml m2 | R30: 44 | S30: 44 | T30: 0 | U30: =F40*G40 | V30: 0 | W30: 0 | X30: =IFERROR(ROUNDUP((Q40/I40)/0.5,0)*0.5,0) | Y30: 0 | Z30: =IF(I40=0,J40*K40,I40*J40*K40) | AA30: 1 | AB30: =$N$126 | AC30: 0 | AD30: =SUM(M40*N40)+M40
A31: PRESUPUESTO | B31: 41 | C31: 39 | D31: MURO - CURVAS / REGATA LED / AISLANTE MURO | E31: muro | F31: muro_curvas_chopo_para_pintar_chopo_5mm_a_2_caras_minimo_1m2_por_tira | G31: Muro | H31: Curvas | I31: Chopo | J31: Para Pintar Chopo 5mm a 2 caras (Minimo 1m2 por tira) | L31: Ancho | M31: Fondo | N31: Altura | O31: ml / m2 | P31: UDS | Q31: €/ml m2 | R31: 58 | S31: 58 | T31: 0 | U31: =F41*G41 | V31: 0 | W31: 0 | X31: =IFERROR(ROUNDUP((Q41/I41)/0.5,0)*0.5,0) | Y31: 0 | Z31: =IF(I41=0,J41*K41,I41*J41*K41) | AA31: 1 | AB31: =$N$126 | AC31: 0 | AD31: =SUM(M41*N41)+M41
A32: PRESUPUESTO | B32: 42 | C32: 39 | D32: MURO - CURVAS / REGATA LED / AISLANTE MURO | E32: muro | F32: muro_tapetas_mdf_5mm_minimo_1m2_por_tira | G32: Muro | H32: Tapetas | I32: MDF | J32: 5mm (Minimo 1m2 por tira) | L32: Ancho | M32: Fondo | N32: Altura | O32: ml / m2 | P32: UDS | Q32: €/ml m2 | R32: 5 | S32: 5 | T32: 0 | U32: =F42*G42 | V32: 0 | W32: 0 | X32: =IFERROR(ROUNDUP((Q42/I42)/0.5,0)*0.5,0) | Y32: 0 | Z32: =IF(I42=0,J42*K42,I42*J42*K42) | AA32: 1 | AB32: =$N$64 | AC32: 0 | AD32: =SUM(M42*N42)+M42
A33: PRESUPUESTO | B33: 43 | C33: 39 | D33: MURO - CURVAS / REGATA LED / AISLANTE MURO | E33: muro | F33: muro_proceso_regata_regata_led_recta | G33: Muro | H33: Proceso | I33: Regata | J33: Regata Led Recta | L33: Ancho | M33: Fondo | N33: Altura | O33: ml / m2 | P33: UDS | Q33: €/ml m2 | R33: 5 | S33: 5 | T33: 0 | V33: 0 | W33: 0 | X33: =IFERROR(ROUNDUP((Q43/I43)/0.5,0)*0.5,0) | Y33: 0 | Z33: =IF(I43=0,J43*K43,I43*J43*K43) | AA33: 1 | AB33: =$N$14 | AC33: 0 | AD33: =SUM(M43*N43)+M43
A34: PRESUPUESTO | B34: 44 | C34: 39 | D34: MURO - CURVAS / REGATA LED / AISLANTE MURO | E34: muro | F34: muro_proceso_regata_regata_led_diagonal_o_curva | G34: Muro | H34: Proceso | I34: Regata | J34: Regata Led Diagonal o Curva | L34: Ancho | M34: Fondo | N34: Altura | O34: ml / m2 | P34: UDS | Q34: €/ml m2 | R34: 10 | S34: 10 | T34: 0 | V34: 0 | W34: 0 | X34: =IFERROR(ROUNDUP((Q44/I44)/0.5,0)*0.5,0) | Y34: 0 | Z34: =IF(I44=0,J44*K44,I44*J44*K44) | AA34: 1 | AB34: =$N$14 | AC34: 0 | AD34: =SUM(M44*N44)+M44
A35: PRESUPUESTO | B35: 45 | C35: 39 | D35: MURO - CURVAS / REGATA LED / AISLANTE MURO | E35: muro | F35: muro_aislante_lana_roca_panel_acustico | G35: Muro | H35: Aislante | I35: Lana Roca | J35: Panel acustico | L35: Ancho | M35: Fondo | N35: Altura | O35: ml / m2 | P35: UDS | Q35: €/ml m2 | R35: 3 | S35: 3 | T35: 0 | U35: =F45*G45 | V35: 0 | W35: 0 | X35: =IFERROR(ROUNDUP((Q45/I45)/0.5,0)*0.5,0) | Y35: 0 | Z35: =IF(I45=0,J45*K45,I45*J45*K45) | AA35: 1 | AB35: =$N$46 | AC35: 0 | AD35: =SUM(M45*N45)+M45
A36: PRESUPUESTO | B36: 48 | C36: 47 | D36: BANNER | E36: banner | F36: banner_banner_chopo_banner_1_cara_chopo_5mm_estructura_pino_grosor_estandar_0_05m | G36: Banner | H36: Banner | I36: Chopo | J36: Banner 1 cara Chopo 5mm + Estructura Pino (Grosor Estandar 0,05m) | L36: Largo | M36: Altura | N36: Grosor | O36: m2 | P36: UDS | Q36: €/m2 | R36: 23 | S36: 23 | T36: 0 | U36: =F48*G48 | V36: 0 | W36: 0 | X36: =IFERROR(ROUNDUP((Q48/I48)/0.5,0)*0.5,0) | Y36: 0 | Z36: =IF(I48=0,J48*K48,I48*J48*K48) | AA36: 1 | AB36: =$N$54 | AC36: 0 | AD36: =SUM(M48*N48)+M48
A37: PRESUPUESTO | B37: 49 | C37: 47 | D37: BANNER | E37: banner | F37: banner_banner_chopo_banner_2_caras_chopo_5mm_estructura_pino_grosor_estandar_0_055m | G37: Banner | H37: Banner | I37: Chopo | J37: Banner 2 caras Chopo 5mm + Estructura Pino (Grosor Estandar 0,055m) | L37: Largo | M37: Altura | N37: Grosor | O37: m2 | P37: UDS | Q37: €/m2 | R37: 37 | S37: 37 | T37: 0 | U37: =F49*G49 | V37: 0 | W37: 0 | X37: =IFERROR(ROUNDUP((Q49/I49)/0.5,0)*0.5,0) | Y37: 0 | Z37: =IF(I49=0,J49*K49,I49*J49*K49) | AA37: 1 | AB37: =$N$54 | AC37: 0 | AD37: =SUM(M49*N49)+M49
